Logging is configured.
======================================================= test session starts ========================================================
platform win32 -- Python 3.12.4, pytest-8.3.2, pluggy-1.5.0
rootdir: C:\Users\150194\OneDrive - Arrow Electronics, Inc\Documents\Python\pytest-project
configfile: pytest.ini
plugins: allure-pytest-2.13.5, html-4.1.1, html-reporter-0.2.9, metadata-3.1.1
collected 11 items / 10 deselected / 1 selected

tests/api/test_api_todo_pixegami.py::test_api_get_task_by_invalid_id Get task by task id: 1000 which is not present.

---------------------------------------------------------- live log call -----------------------------------------------------------
2024-08-08 12:30:05 INFO Get task by task id: 1000 which is not present.
Starting new HTTPS connection (1): todo.pixegami.io:443
https://todo.pixegami.io:443 "GET /get-task/1000 HTTP/11" 404 32
{'detail': 'Task 1000 not found'}
404
PASSED

================================================= 1 passed, 10 deselected in 5.30s =================================================
